Workbook

Sheet Demand Base Matrix
A1: Customer Journey Stage | B1: Stage | C1: Role | D1: Project Start M0 | E1: Project Start M1 | F1: Project Mid | G1: Project End M-1 | H1: Project End M0 | I1: Project End M1 | J1: Project End M1+ | N1: VIBE Tag | O1: Role | P1: Project Start M0 | Q1: Project Start M1 | R1: Project Mid | S1: Project End M-1 | T1: Project End M0 | U1: Project End M1 | V1: Project End M1+
A2: Validate | B2: Discovery and App Go-Live | C2: PM | D2: 10 | E2: 10 | F2: 2 | G2: 0 | H2: 0 | I2: 0 | J2: 0 | K2: LM Bucket | L2: Multiplier | N2: Bond | O2: PM | P2: =SUMIFS(D$2:D$91,$A$2:$A$91,$N2,$C$2:$C$91,$O2) -> 10 | Q2: =SUMIFS(E$2:E$91,$A$2:$A$91,$N2,$C$2:$C$91,$O2) -> 10 | R2: =SUMIFS(F$2:F$91,$A$2:$A$91,$N2,$C$2:$C$91,$O2) -> 10 | S2: =SUMIFS(G$2:G$91,$A$2:$A$91,$N2,$C$2:$C$91,$O2) -> 50 | T2: =SUMIFS(H$2:H$91,$A$2:$A$91,$N2,$C$2:$C$91,$O2) -> 28 | U2: =SUMIFS(I$2:I$91,$A$2:$A$91,$N2,$C$2:$C$91,$O2) -> 8 | V2: =SUMIFS(J$2:J$91,$A$2:$A$91,$N2,$C$2:$C$91,$O2) -> 8 | X2: Final Multiplier Chart | AF2: Orbit A | AG2: Orbit B | AH2: Orbit C&D | AJ2: LMs | AK2: Multiplier | AL2: Dx/Tx | AM2: Multiplier | AN2: Non-Standard Data | AO2: Multiplier | AP2: Non-Standard Metric | AQ2: Multiplier | AR2: IVMS Configuration | AS2: Multiplier
A3: Validate | B3: Imagery Planning, Decisioning & Acquision | C3: PM | D3: 5 | E3: 5 | F3: 5 | G3: 0 | H3: 0 | I3: 0 | J3: 0 | K3: 1000 | L3: 0.75 | N3: Explore | O3: PM | P3: =SUMIFS(D$2:D$91,$A$2:$A$91,$N3,$C$2:$C$91,$O3) -> 15 | Q3: =SUMIFS(E$2:E$91,$A$2:$A$91,$N3,$C$2:$C$91,$O3) -> 30 | R3: =SUMIFS(F$2:F$91,$A$2:$A$91,$N3,$C$2:$C$91,$O3) -> 10 | S3: =SUMIFS(G$2:G$91,$A$2:$A$91,$N3,$C$2:$C$91,$O3) -> 40 | T3: =SUMIFS(H$2:H$91,$A$2:$A$91,$N3,$C$2:$C$91,$O3) -> 40 | U3: =SUMIFS(I$2:I$91,$A$2:$A$91,$N3,$C$2:$C$91,$O3) -> 10 | V3: =SUMIFS(J$2:J$91,$A$2:$A$91,$N3,$C$2:$C$91,$O3) -> 5 | AE3: Validate | AF3: 1.75 | AG3: 1.5 | AH3: 1 | AJ3: 1000 | AK3: 0.75 | AL3: Dx | AM3: 1 | AN3: High | AO3: 1.5 | AP3: High | AQ3: 2 | AR3: High | AS3: 2
A4: Validate | B4: GIS - Correction / Validation | C4: PM | D4: 0 | E4: 0 | F4: 0 | G4: 20 | H4: 0 | I4: 0 | J4: 0 | K4: 5000 | L4: 1 | N4: Integrate | O4: PM | P4: =SUMIFS(D$2:D$91,$A$2:$A$91,$N4,$C$2:$C$91,$O4) -> 10 | Q4: =SUMIFS(E$2:E$91,$A$2:$A$91,$N4,$C$2:$C$91,$O4) -> 20 | R4: =SUMIFS(F$2:F$91,$A$2:$A$91,$N4,$C$2:$C$91,$O4) -> 10 | S4: =SUMIFS(G$2:G$91,$A$2:$A$91,$N4,$C$2:$C$91,$O4) -> 60 | T4: =SUMIFS(H$2:H$91,$A$2:$A$91,$N4,$C$2:$C$91,$O4) -> 28 | U4: =SUMIFS(I$2:I$91,$A$2:$A$91,$N4,$C$2:$C$91,$O4) -> 8 | V4: =SUMIFS(J$2:J$91,$A$2:$A$91,$N4,$C$2:$C$91,$O4) -> 8 | AE4: Integrate | AF4: 1.25 | AG4: 1 | AH4: 0.8 | AJ4: 5000 | AK4: 1 | AL4: Tx | AM4: 1.5 | AN4: Medium | AO4: 1.25 | AP4: Medium | AQ4: 1.5 | AR4: Medium | AS4: 1.5
A5: Validate | B5: Model Run | C5: PM | D5: 0 | E5: 0 | F5: 0 | G5: 20 | H5: 0 | I5: 0 | J5: 0 | K5: 10000 | L5: 1.25 | N5: Validate | O5: PM | P5: =SUMIFS(D$2:D$91,$A$2:$A$91,$N5,$C$2:$C$91,$O5) -> 15 | Q5: =SUMIFS(E$2:E$91,$A$2:$A$91,$N5,$C$2:$C$91,$O5) -> 15 | R5: =SUMIFS(F$2:F$91,$A$2:$A$91,$N5,$C$2:$C$91,$O5) -> 7 | S5: =SUMIFS(G$2:G$91,$A$2:$A$91,$N5,$C$2:$C$91,$O5) -> 40 | T5: =SUMIFS(H$2:H$91,$A$2:$A$91,$N5,$C$2:$C$91,$O5) -> 60 | U5: =SUMIFS(I$2:I$91,$A$2:$A$91,$N5,$C$2:$C$91,$O5) -> 10 | V5: =SUMIFS(J$2:J$91,$A$2:$A$91,$N5,$C$2:$C$91,$O5) -> 4 | Y5: Validate | Z5: A | AA5: 1.75 | AE5: Bond | AF5: 1.225 | AG5: 1.05 | AH5: 0.7 | AJ5: 10000 | AK5: 1.25 | AN5: Low | AO5: 1 | AP5: Low | AQ5: 1 | AR5: Low | AS5: 1
A6: Validate | B6: Analysis | C6: PM | D6: 0 | E6: 0 | F6: 0 | G6: 0 | H6: 40 | I6: 0 | J6: 0 | K6: 25000 | L6: 1.5 | N6: Bond | O6: CSM | P6: =SUMIFS(D$2:D$91,$A$2:$A$91,$N6,$C$2:$C$91,$O6) -> 5 | Q6: =SUMIFS(E$2:E$91,$A$2:$A$91,$N6,$C$2:$C$91,$O6) -> 5 | R6: =SUMIFS(F$2:F$91,$A$2:$A$91,$N6,$C$2:$C$91,$O6) -> 5 | S6: =SUMIFS(G$2:G$91,$A$2:$A$91,$N6,$C$2:$C$91,$O6) -> 10 | T6: =SUMIFS(H$2:H$91,$A$2:$A$91,$N6,$C$2:$C$91,$O6) -> 19 | U6: =SUMIFS(I$2:I$91,$A$2:$A$91,$N6,$C$2:$C$91,$O6) -> 11 | V6: =SUMIFS(J$2:J$91,$A$2:$A$91,$N6,$C$2:$C$91,$O6) -> 1 | Y6: Integrate | Z6: A | AA6: 1.25 | AE6: Explore | AF6: 1.75 | AG6: 1.5 | AH6: 1 | AJ6: 25000 | AK6: 1.5
A7: Validate | B7: Results Presentation and Change Management | C7: PM | D7: 0 | E7: 0 | F7: 0 | G7: 0 | H7: 10 | I7: 0 | J7: 0 | K7: 100000 | L7: 2 | N7: Explore | O7: CSM | P7: =SUMIFS(D$2:D$91,$A$2:$A$91,$N7,$C$2:$C$91,$O7) -> 20 | Q7: =SUMIFS(E$2:E$91,$A$2:$A$91,$N7,$C$2:$C$91,$O7) -> 10 | R7: =SUMIFS(F$2:F$91,$A$2:$A$91,$N7,$C$2:$C$91,$O7) -> 20 | S7: =SUMIFS(G$2:G$91,$A$2:$A$91,$N7,$C$2:$C$91,$O7) -> 5 | T7: =SUMIFS(H$2:H$91,$A$2:$A$91,$N7,$C$2:$C$91,$O7) -> 60 | U7: =SUMIFS(I$2:I$91,$A$2:$A$91,$N7,$C$2:$C$91,$O7) -> 20 | V7: =SUMIFS(J$2:J$91,$A$2:$A$91,$N7,$C$2:$C$91,$O7) -> 10 | Y7: Bond | Z7: A | AA7: 1.225 | AJ7: 100000 | AK7: 2
A8: Validate | B8: Ongoing - Adoption Support | C8: PM | D8: 0 | E8: 0 | F8: 0 | G8: 0 | H8: 10 | I8: 10 | J8: 4 | N8: Integrate | O8: CSM | P8: =SUMIFS(D$2:D$91,$A$2:$A$91,$N8,$C$2:$C$91,$O8) -> 27 | Q8: =SUMIFS(E$2:E$91,$A$2:$A$91,$N8,$C$2:$C$91,$O8) -> 30 | R8: =SUMIFS(F$2:F$91,$A$2:$A$91,$N8,$C$2:$C$91,$O8) -> 36 | S8: =SUMIFS(G$2:G$91,$A$2:$A$91,$N8,$C$2:$C$91,$O8) -> 20 | T8: =SUMIFS(H$2:H$91,$A$2:$A$91,$N8,$C$2:$C$91,$O8) -> 38 | U8: =SUMIFS(I$2:I$91,$A$2:$A$91,$N8,$C$2:$C$91,$O8) -> 24 | V8: =SUMIFS(J$2:J$91,$A$2:$A$91,$N8,$C$2:$C$91,$O8) -> 24 | Y8: Explore | Z8: A | AA8: 1.75
A9: Validate | B9: Sales Handover + Kick off | C9: CSM | D9: 3 | E9: 0 | F9: 0 | G9: 0 | H9: 0 | I9: 0 | J9: 0 | N9: Validate | O9: CSM | P9: =SUMIFS(D$2:D$91,$A$2:$A$91,$N9,$C$2:$C$91,$O9) -> 16 | Q9: =SUMIFS(E$2:E$91,$A$2:$A$91,$N9,$C$2:$C$91,$O9) -> 24 | R9: =SUMIFS(F$2:F$91,$A$2:$A$91,$N9,$C$2:$C$91,$O9) -> 14 | S9: =SUMIFS(G$2:G$91,$A$2:$A$91,$N9,$C$2:$C$91,$O9) -> 15 | T9: =SUMIFS(H$2:H$91,$A$2:$A$91,$N9,$C$2:$C$91,$O9) -> 37 | U9: =SUMIFS(I$2:I$91,$A$2:$A$91,$N9,$C$2:$C$91,$O9) -> 19 | V9: =SUMIFS(J$2:J$91,$A$2:$A$91,$N9,$C$2:$C$91,$O9) -> 0 | Y9: Validate | Z9: B | AA9: 1.5
A10: Validate | B10: Discovery + Imagery | C10: CSM | D10: 8 | E10: 8 | F10: 0 | G10: 0 | H10: 0 | I10: 0 | J10: 0 | N10: Bond | O10: Analyst 1 | P10: =SUMIFS(D$2:D$91,$A$2:$A$91,$N10,$C$2:$C$91,"Analyst") -> 10 | Q10: =SUMIFS(E$2:E$91,$A$2:$A$91,$N10,$C$2:$C$91,"Analyst") -> 12 | R10: =SUMIFS(F$2:F$91,$A$2:$A$91,$N10,$C$2:$C$91,"Analyst") -> 11 | S10: =SUMIFS(G$2:G$91,$A$2:$A$91,$N10,$C$2:$C$91,"Analyst") -> 0 | T10: =SUMIFS(H$2:H$91,$A$2:$A$91,$N10,$C$2:$C$91,"Analyst") -> 89 | U10: =SUMIFS(I$2:I$91,$A$2:$A$91,$N10,$C$2:$C$91,"Analyst") -> 20 | V10: =SUMIFS(J$2:J$91,$A$2:$A$91,$N10,$C$2:$C$91,"Analyst") -> 1 | Y10: Integrate | Z10: B | AA10: 1
A11: Validate | B11: Business Case | C11: CSM | D11: 0 | E11: 1 | F11: 4 | G11: 0 | H11: 0 | I11: 0 | J11: 0 | N11: Explore | O11: Analyst 1 | P11: =SUMIFS(D$2:D$91,$A$2:$A$91,$N11,$C$2:$C$91,"Analyst") -> 0 | Q11: =SUMIFS(E$2:E$91,$A$2:$A$91,$N11,$C$2:$C$91,"Analyst") -> 0 | R11: =SUMIFS(F$2:F$91,$A$2:$A$91,$N11,$C$2:$C$91,"Analyst") -> 0 | S11: =SUMIFS(G$2:G$91,$A$2:$A$91,$N11,$C$2:$C$91,"Analyst") -> 0 | T11: =SUMIFS(H$2:H$91,$A$2:$A$91,$N11,$C$2:$C$91,"Analyst") -> 0 | U11: =SUMIFS(I$2:I$91,$A$2:$A$91,$N11,$C$2:$C$91,"Analyst") -> 0 | V11: =SUMIFS(J$2:J$91,$A$2:$A$91,$N11,$C$2:$C$91,"Analyst") -> 0 | Y11: Bond | Z11: B | AA11: 1.05
A12: Validate | B12: App Go Live + Confirm Requirements | C12: CSM | D12: 0 | E12: 10 | F12: 0 | G12: 0 | H12: 0 | I12: 0 | J12: 0 | L12: PS Work | N12: Integrate | O12: Analyst 1 | P12: =SUMIFS(D$2:D$91,$A$2:$A$91,$N12,$C$2:$C$91,"Analyst") -> 20 | Q12: =SUMIFS(E$2:E$91,$A$2:$A$91,$N12,$C$2:$C$91,"Analyst") -> 22 | R12: =SUMIFS(F$2:F$91,$A$2:$A$91,$N12,$C$2:$C$91,"Analyst") -> 11 | S12: =SUMIFS(G$2:G$91,$A$2:$A$91,$N12,$C$2:$C$91,"Analyst") -> 0 | T12: =SUMIFS(H$2:H$91,$A$2:$A$91,$N12,$C$2:$C$91,"Analyst") -> 89 | U12: =SUMIFS(I$2:I$91,$A$2:$A$91,$N12,$C$2:$C$91,"Analyst") -> 20 | V12: =SUMIFS(J$2:J$91,$A$2:$A$91,$N12,$C$2:$C$91,"Analyst") -> 1 | Y12: Explore | Z12: B | AA12: 1.5
A13: Validate | B13: Analysis | C13: CSM | D13: 0 | E13: 0 | F13: 5 | G13: 10 | H13: 0 | I13: 0 | J13: 0 | L13: Validate as a multiplier | N13: Validate | O13: Analyst 1 | P13: =SUMIFS(D$2:D$91,$A$2:$A$91,$N13,$C$2:$C$91,"Analyst") -> 30 | Q13: =SUMIFS(E$2:E$91,$A$2:$A$91,$N13,$C$2:$C$91,"Analyst") -> 22 | R13: =SUMIFS(F$2:F$91,$A$2:$A$91,$N13,$C$2:$C$91,"Analyst") -> 12 | S13: =SUMIFS(G$2:G$91,$A$2:$A$91,$N13,$C$2:$C$91,"Analyst") -> 0 | T13: =SUMIFS(H$2:H$91,$A$2:$A$91,$N13,$C$2:$C$91,"Analyst") -> 89 | U13: =SUMIFS(I$2:I$91,$A$2:$A$91,$N13,$C$2:$C$91,"Analyst") -> 20 | V13: =SUMIFS(J$2:J$91,$A$2:$A$91,$N13,$C$2:$C$91,"Analyst") -> 1 | Y13: Validate | Z13: C | AA13: 1
A14: Validate | B14: Insights & Recs + FV | C14: CSM | D14: 0 | E14: 0 | F14: 0 | G14: 0 | H14: 32 | I14: 0 | J14: 0 | K14: not sure of bond? | N14: Bond | O14: Analyst 2 | P14: =SUMIFS(D$2:D$91,$A$2:$A$91,$N14,$C$2:$C$91,"Analyst") -> 10 | Q14: =SUMIFS(E$2:E$91,$A$2:$A$91,$N14,$C$2:$C$91,"Analyst") -> 12 | R14: =SUMIFS(F$2:F$91,$A$2:$A$91,$N14,$C$2:$C$91,"Analyst") -> 11 | S14: =SUMIFS(G$2:G$91,$A$2:$A$91,$N14,$C$2:$C$91,"Analyst") -> 0 | T14: =SUMIFS(H$2:H$91,$A$2:$A$91,$N14,$C$2:$C$91,"Analyst") -> 89 | U14: =SUMIFS(I$2:I$91,$A$2:$A$91,$N14,$C$2:$C$91,"Analyst") -> 20 | V14: =SUMIFS(J$2:J$91,$A$2:$A$91,$N14,$C$2:$C$91,"Analyst") -> 1 | Y14: Integrate | Z14: C | AA14: 0.8
A15: Validate | B15: Change Management + Conversion | C15: CSM | D15: 5 | E15: 5 | F15: 5 | G15: 5 | H15: 5 | I15: 19 | J15: 0 | K15: {=SUM(D9:E15,G9:J15)+SUM(F9:F15*6)} -> 195 | L15: =K15*1.75 -> 341.25 | N15: Explore | O15: Analyst 2 | P15: =SUMIFS(D$2:D$91,$A$2:$A$91,$N15,$C$2:$C$91,"Analyst") -> 0 | Q15: =SUMIFS(E$2:E$91,$A$2:$A$91,$N15,$C$2:$C$91,"Analyst") -> 0 | R15: =SUMIFS(F$2:F$91,$A$2:$A$91,$N15,$C$2:$C$91,"Analyst") -> 0 | S15: =SUMIFS(G$2:G$91,$A$2:$A$91,$N15,$C$2:$C$91,"Analyst") -> 0 | T15: =SUMIFS(H$2:H$91,$A$2:$A$91,$N15,$C$2:$C$91,"Analyst") -> 0 | U15: =SUMIFS(I$2:I$91,$A$2:$A$91,$N15,$C$2:$C$91,"Analyst") -> 0 | V15: =SUMIFS(J$2:J$91,$A$2:$A$91,$N15,$C$2:$C$91,"Analyst") -> 0 | Y15: Bond | Z15: C | AA15: 0.7
A16: Validate | B16: Discovery, Original Shapefile Ingestion App Go-Live & Data QC | C16: Analyst | D16: 30 | E16: 10 | F16: 1 | G16: 0 | H16: 0 | I16: 0 | J16: 0 | N16: Integrate | O16: Analyst 2 | P16: =SUMIFS(D$2:D$91,$A$2:$A$91,$N16,$C$2:$C$91,"Analyst") -> 20 | Q16: =SUMIFS(E$2:E$91,$A$2:$A$91,$N16,$C$2:$C$91,"Analyst") -> 22 | R16: =SUMIFS(F$2:F$91,$A$2:$A$91,$N16,$C$2:$C$91,"Analyst") -> 11 | S16: =SUMIFS(G$2:G$91,$A$2:$A$91,$N16,$C$2:$C$91,"Analyst") -> 0 | T16: =SUMIFS(H$2:H$91,$A$2:$A$91,$N16,$C$2:$C$91,"Analyst") -> 89 | U16: =SUMIFS(I$2:I$91,$A$2:$A$91,$N16,$C$2:$C$91,"Analyst") -> 20 | V16: =SUMIFS(J$2:J$91,$A$2:$A$91,$N16,$C$2:$C$91,"Analyst") -> 1 | Y16: Explore | Z16: C | AA16: 1
A17: Validate | B17: Imagery Planning, Decisioning & Acquision | C17: Analyst | D17: 0 | E17: 12 | F17: 1 | G17: 0 | H17: 0 | I17: 0 | J17: 0 | N17: Validate | O17: Analyst 2 | P17: =SUMIFS(D$2:D$91,$A$2:$A$91,$N17,$C$2:$C$91,"Analyst") -> 30 | Q17: =SUMIFS(E$2:E$91,$A$2:$A$91,$N17,$C$2:$C$91,"Analyst") -> 22 | R17: =SUMIFS(F$2:F$91,$A$2:$A$91,$N17,$C$2:$C$91,"Analyst") -> 12 | S17: =SUMIFS(G$2:G$91,$A$2:$A$91,$N17,$C$2:$C$91,"Analyst") -> 0 | T17: =SUMIFS(H$2:H$91,$A$2:$A$91,$N17,$C$2:$C$91,"Analyst") -> 89 | U17: =SUMIFS(I$2:I$91,$A$2:$A$91,$N17,$C$2:$C$91,"Analyst") -> 20 | V17: =SUMIFS(J$2:J$91,$A$2:$A$91,$N17,$C$2:$C$91,"Analyst") -> 1 | Y17: Validate | Z17: D | AA17: 1
A18: Validate | B18: Ingest Corrected / Validated Shapefile & Bbox Creation | C18: Analyst | D18: 0 | E18: 0 | F18: 10 | G18: 0 | H18: 0 | I18: 0 | J18: 0 | N18: Bond | O18: SE | P18: =SUMIFS(D$2:D$91,$A$2:$A$91,$N18,$C$2:$C$91,$O18) -> 24 | Q18: =SUMIFS(E$2:E$91,$A$2:$A$91,$N18,$C$2:$C$91,$O18) -> 23 | R18: =SUMIFS(F$2:F$91,$A$2:$A$91,$N18,$C$2:$C$91,$O18) -> 0 | S18: =SUMIFS(G$2:G$91,$A$2:$A$91,$N18,$C$2:$C$91,$O18) -> 10 | T18: =SUMIFS(H$2:H$91,$A$2:$A$91,$N18,$C$2:$C$91,$O18) -> 25 | U18: =SUMIFS(I$2:I$91,$A$2:$A$91,$N18,$C$2:$C$91,$O18) -> 0 | V18: =SUMIFS(J$2:J$91,$A$2:$A$91,$N18,$C$2:$C$91,$O18) -> 0 | Y18: Integrate | Z18: D | AA18: 0.8
A19: Validate | B19: Model Run | C19: Analyst | D19: 0 | E19: 0 | F19: 0 | G19: 0 | H19: 25 | I19: 0 | J19: 0 | N19: Explore | O19: SE | P19: =SUMIFS(D$2:D$91,$A$2:$A$91,$N19,$C$2:$C$91,$O19) -> 0 | Q19: =SUMIFS(E$2:E$91,$A$2:$A$91,$N19,$C$2:$C$91,$O19) -> 0 | R19: =SUMIFS(F$2:F$91,$A$2:$A$91,$N19,$C$2:$C$91,$O19) -> 0 | S19: =SUMIFS(G$2:G$91,$A$2:$A$91,$N19,$C$2:$C$91,$O19) -> 0 | T19: =SUMIFS(H$2:H$91,$A$2:$A$91,$N19,$C$2:$C$91,$O19) -> 0 | U19: =SUMIFS(I$2:I$91,$A$2:$A$91,$N19,$C$2:$C$91,$O19) -> 0 | V19: =SUMIFS(J$2:J$91,$A$2:$A$91,$N19,$C$2:$C$91,$O19) -> 0 | Y19: Bond | Z19: D | AA19: 0.7
A20: Validate | B20: Analysis | C20: Analyst | D20: 0 | E20: 0 | F20: 0 | G20: 0 | H20: 60 | I20: 0 | J20: 0 | N20: Integrate | O20: SE | P20: =SUMIFS(D$2:D$91,$A$2:$A$91,$N20,$C$2:$C$91,$O20) -> 24 | Q20: =SUMIFS(E$2:E$91,$A$2:$A$91,$N20,$C$2:$C$91,$O20) -> 23 | R20: =SUMIFS(F$2:F$91,$A$2:$A$91,$N20,$C$2:$C$91,$O20) -> 0 | S20: =SUMIFS(G$2:G$91,$A$2:$A$91,$N20,$C$2:$C$91,$O20) -> 10 | T20: =SUMIFS(H$2:H$91,$A$2:$A$91,$N20,$C$2:$C$91,$O20) -> 25 | U20: =SUMIFS(I$2:I$91,$A$2:$A$91,$N20,$C$2:$C$91,$O20) -> 0 | V20: =SUMIFS(J$2:J$91,$A$2:$A$91,$N20,$C$2:$C$91,$O20) -> 0 | Y20: Explore | Z20: D | AA20: 1
A21: Validate | B21: Results Presentation and Change Management | C21: Analyst | D21: 0 | E21: 0 | F21: 0 | G21: 0 | H21: 4 | I21: 0 | J21: 0 | N21: Validate | O21: SE | P21: =SUMIFS(D$2:D$91,$A$2:$A$91,$N21,$C$2:$C$91,$O21) -> 20 | Q21: =SUMIFS(E$2:E$91,$A$2:$A$91,$N21,$C$2:$C$91,$O21) -> 23 | R21: =SUMIFS(F$2:F$91,$A$2:$A$91,$N21,$C$2:$C$91,$O21) -> 8 | S21: =SUMIFS(G$2:G$91,$A$2:$A$91,$N21,$C$2:$C$91,$O21) -> 0 | T21: =SUMIFS(H$2:H$91,$A$2:$A$91,$N21,$C$2:$C$91,$O21) -> 25 | U21: =SUMIFS(I$2:I$91,$A$2:$A$91,$N21,$C$2:$C$91,$O21) -> 0 | V21: =SUMIFS(J$2:J$91,$A$2:$A$91,$N21,$C$2:$C$91,$O21) -> 0
A22: Validate | B22: Ongoing - Adoption Support | C22: Analyst | D22: 0 | E22: 0 | F22: 0 | G22: 0 | H22: 0 | I22: 20 | J22: 1
A23: Validate | B23: Image Acquisition & Ingestion | C23: SE | D23: 20 | E23: 23 | F23: 8 | G23: 0 | H23: 0 | I23: 0 | J23: 0
A24: Validate | B24: Model Run | C24: SE | D24: 0 | E24: 0 | F24: 0 | G24: 0 | H24: 25 | I24: 0 | J24: 0
A25: Validate | B25: Analysis | C25: SE | D25: 0 | E25: 0 | F25: 0 | G25: 0 | H25: 0 | I25: 0 | J25: 0
A26: Validate | B26: Results Presentation and Change Management | C26: SE | D26: 0 | E26: 0 | F26: 0 | G26: 0 | H26: 0 | I26: 0 | J26: 0
A27: Validate | B27: Ongoing - Adoption Support | C27: SE | D27: 0 | E27: 0 | F27: 0 | G27: 0 | H27: 0 | I27: 0 | J27: 0
A28: Integrate | B28: Discovery | C28: PM | D28: 5 | E28: 10 | F28: 0 | G28: 0 | H28: 0 | I28: 0 | J28: 0
A29: Integrate | B29: Imagery Planning, Decisioning & Acquision | C29: PM | D29: 5 | E29: 10 | F29: 5 | G29: 0 | H29: 0 | I29: 0 | J29: 0
A30: Integrate | B30: GIS - Correction / Validation | C30: PM | D30: 0 | E30: 0 | F30: 5 | G30: 15 | H30: 0 | I30: 0 | J30: 0 | K30: initial thought
A31: Integrate | B31: Model Run | C31: PM | D31: 0 | E31: 0 | F31: 0 | G31: 15 | H31: 0 | I31: 0 | J31: 0 | K31: 3 hrs for internal analysis | L31: 20 hrs
A32: Integrate | B32: Analysis | C32: PM | D32: 0 | E32: 0 | F32: 0 | G32: 30 | H32: 10 | I32: 0 | J32: 0
A33: Integrate | B33: Results Presentation and Change Management | C33: PM | D33: 0 | E33: 0 | F33: 0 | G33: 0 | H33: 10 | I33: 0 | J33: 0 | K33: 0.75X of Validate discovery
A34: Integrate | B34: Ongoing - Adoption Support | C34: PM | D34: 0 | E34: 0 | F34: 0 | G34: 0 | H34: 8 | I34: 8 | J34: 8
A35: Integrate | B35: Sales Handover + Kick off | C35: CSM | D35: 0 | E35: 0 | F35: 0 | G35: 0 | H35: 0 | I35: 0 | J35: 0
A36: Integrate | B36: Discovery + Imagery | C36: CSM | D36: 12 | E36: 0 | F36: 0 | G36: 0 | H36: 0 | I36: 0 | J36: 0
A37: Integrate | B37: Business Case | C37: CSM | D37: 0 | E37: 0 | F37: 0 | G37: 0 | H37: 0 | I37: 0 | J37: 0
A38: Integrate | B38: App Go Live + Confirm Requirements | C38: CSM | D38: 0 | E38: 20 | F38: 15 | G38: 0 | H38: 0 | I38: 0 | J38: 0
A39: Integrate | B39: Analysis | C39: CSM | D39: 0 | E39: 0 | F39: 6 | G39: 10 | H39: 0 | I39: 0 | J39: 0
A40: Integrate | B40: Insights & Recs + FV | C40: CSM | D40: 0 | E40: 0 | F40: 0 | G40: 0 | H40: 28 | I40: 0 | J40: 0
...

Sheet Project List
A1: Summary | B1: SF Account Name | C1: CS Type | D1: Assigned Product Consultant.displayName | E1: Assigned Project Manager.displayName | F1: Assigned Business Analyst.displayName | G1: Assigned Business Analyst 2.displayName | H1: Analyst 1 Load% (1 to 100) | I1: Orbit | J1: Dx LMs | K1: Tx LMs | L1: Required Delivery Date (RDD) | M1: Estimated Delivery Date (EDD) | N1: Delivery Year | O1: Created | P1: Product | Q1: Created | R1: Delivery Date | S1: Created Main | T1: Delivery Date Main | U1: Total LMs | V1: Analytics Start Date | W1: LM Multiplier | X1: Delivery Month | Y1: Dx/Tx | Z1: Non-Standard Data | AA1: Non-Standard Metric | AB1: IVMS Configuration | AC1: Dx/Tx Multiplier | AD1: Non-Standard Data Multiplier | AE1: Non-Standard Metric Multiplier | AF1: IVMS Configuration Multiplier | AG1: Project Start M0 | AH1: Project Start M1 | AI1: Project Mid | AJ1: Project End M-1 | AK1: Project End M0 | AL1: Project End M1 | AM1: Project End M1+
A2: [2026 SaaS Y2] Adams-Columbia Electric Coop | B2: Adams-Columbia Electric Cooperative | C2: Bond | D2: Meryl Gibbs | E2: Shashank Sharma | F2: Kshitiz Agrawal | I2: =IFERROR(INDEX('Customer 360'!F:F,MATCH(B2,'Customer 360'!A:A,0)),"-") -> D | J2: 3000 | L2: 46258 | M2: 46258 | N2: 2026 | O2: 46082 | P2: IVMS | Q2: =O2 -> 46082 | R2: =IFERROR(IF(M2<>"",M2,IF(L2<>"",L2,INDEX('CSM RDD'!B:B,MATCH(B2,'CSM RDD'!A:A,0)))),"-") -> 46258 | S2: =IFERROR(EOMONTH(Q2,-1)+1,"") -> 46082 | T2: =IFERROR(EOMONTH(R2,-1)+1,"") -> 46235 | U2: =J2+K2 -> 3000 | V2: =IF(C2<>"Validate",DATE(2026,3,1),O2) -> 46082 | W2: =IF(U2=0,1,IF(U2<='Demand Base Matrix'!$K$3,'Demand Base Matrix'!$L$3,IF(U2<='Demand Base Matrix'!$K$4,'Demand Base Matrix'!$L$4,IF(U2<='Demand Base Matrix'!$K$5,'Demand Base Matrix'!$L$5,IF(U2<='Demand Base Matrix'!$K$6,'Demand Base Matrix'!$L$6,IF(U2<='Demand Base Matrix'!$K$7,'Demand Base Matrix'!$L$7)))))) -> 1 | X2: =DATE(YEAR(R2),MONTH(R2),1) -> 46235 | Y2: =IF(K2>0,"Tx","Dx") -> Dx | Z2: Low | AA2: Low | AB2: Low | AC2: =IFERROR(INDEX('Demand Base Matrix'!AM:AM,MATCH(Y2,'Demand Base Matrix'!AL:AL,0)),1) -> 1 | AD2: =IFERROR(INDEX('Demand Base Matrix'!AO:AO,MATCH(Z2,'Demand Base Matrix'!AN:AN,0)),1) -> 1 | AE2: =IFERROR(INDEX('Demand Base Matrix'!AQ:AQ,MATCH(AA2,'Demand Base Matrix'!AP:AP,0)),1) -> 1 | AF2: =IFERROR(INDEX('Demand Base Matrix'!AS:AS,MATCH(AB2,'Demand Base Matrix'!AR:AR,0)),1) -> 1 | AG2: =IF($C2="Validate",(('Demand Base Matrix'!D$2+'Demand Base Matrix'!D$6)*$AC$2*$AD$2*$AE$2+('Demand Base Matrix'!D$3+'Demand Base Matrix'!D$4)*$W$2*$AD$2+'Demand Base Matrix'!D$5*$W$2*$AD$2*$AE$2+'Demand Base Matrix'!D$7+'Demand Base Matrix'!D$8*$AF$2),IF($C2="Integrate",(('Demand Base Matrix'!D$28+'Demand Base Matrix'!D$32)*$AC$2*$AD$2*$AE$2+('Demand Base Matrix'!D$29+'Demand Base Matrix'!D$30)*$W$2*$AD$2+'Demand Base Matrix'!D$31*$W$2*$AD$2*$AE$2+'Demand Base Matrix'!D$33+'Demand Base Matrix'!D$34*$AF$2),IF($C2="Bond",(('Demand Base Matrix'!D$55+'Demand Base Matrix'!D$59)*$AC$2*$AD$2*$AE$2+('Demand Base Matrix'!D$56+'Demand Base Matrix'!D$57)*$W$2*$AD$2+'Demand Base Matrix'!D$58*$W$2*$AD$2*$AE$2+'Demand Base Matrix'!D$60+'Demand Base Matrix'!D$61*$AF$2),IF($C2="Explore",('Demand Base Matrix'!D$82*$AC$2*$AD$2*$AE$2*$AF$2+'Demand Base Matrix'!D$83*$W$2*$AC$2*$AD$2*$AE$2*$AF$2+'Demand Base Matrix'!D$84))))) -> 10 | AH2: =IF($C2="Validate",(('Demand Base Matrix'!E$2+'Demand Base Matrix'!E$6)*$AC$2*$AD$2*$AE$2+('Demand Base Matrix'!E$3+'Demand Base Matrix'!E$4)*$W$2*$AD$2+'Demand Base Matrix'!E$5*$W$2*$AD$2*$AE$2+'Demand Base Matrix'!E$7+'Demand Base Matrix'!E$8*$AF$2),IF($C2="Integrate",(('Demand Base Matrix'!E$28+'Demand Base Matrix'!E$32)*$AC$2*$AD$2*$AE$2+('Demand Base Matrix'!E$29+'Demand Base Matrix'!E$30)*$W$2*$AD$2+'Demand Base Matrix'!E$31*$W$2*$AD$2*$AE$2+'Demand Base Matrix'!E$33+'Demand Base Matrix'!E$34*$AF$2),IF($C2="Bond",(('Demand Base Matrix'!E$55+'Demand Base Matrix'!E$59)*$AC$2*$AD$2*$AE$2+('Demand Base Matrix'!E$56+'Demand Base Matrix'!E$57)*$W$2*$AD$2+'Demand Base Matrix'!E$58*$W$2*$AD$2*$AE$2+'Demand Base Matrix'!E$60+'Demand Base Matrix'!E$61*$AF$2),IF($C2="Explore",('Demand Base Matrix'!E$82*$AC$2*$AD$2*$AE$2*$AF$2+'Demand Base Matrix'!E$83*$W$2*$AC$2*$AD$2*$AE$2*$AF$2+'Demand Base Matrix'!E$84))))) -> 10 | AI2: =IF($C2="Validate",(('Demand Base Matrix'!F$2+'Demand Base Matrix'!F$6)*$AC$2*$AD$2*$AE$2+('Demand Base Matrix'!F$3+'Demand Base Matrix'!F$4)*$W$2*$AD$2+'Demand Base Matrix'!F$5*$W$2*$AD$2*$AE$2+'Demand Base Matrix'!F$7+'Demand Base Matrix'!F$8*$AF$2),IF($C2="Integrate",(('Demand Base Matrix'!F$28+'Demand Base Matrix'!F$32)*$AC$2*$AD$2*$AE$2+('Demand Base Matrix'!F$29+'Demand Base Matrix'!F$30)*$W$2*$AD$2+'Demand Base Matrix'!F$31*$W$2*$AD$2*$AE$2+'Demand Base Matrix'!F$33+'Demand Base Matrix'!F$34*$AF$2),IF($C2="Bond",(('Demand Base Matrix'!F$55+'Demand Base Matrix'!F$59)*$AC$2*$AD$2*$AE$2+('Demand Base Matrix'!F$56+'Demand Base Matrix'!F$57)*$W$2*$AD$2+'Demand Base Matrix'!F$58*$W$2*$AD$2*$AE$2+'Demand Base Matrix'!F$60+'Demand Base Matrix'!F$61*$AF$2),IF($C2="Explore",('Demand Base Matrix'!F$82*$AC$2*$AD$2*$AE$2*$AF$2+'Demand Base Matrix'!F$83*$W$2*$AC$2*$AD$2*$AE$2*$AF$2+'Demand Base Matrix'!F$84))))) -> 10 | AJ2: =IF($C2="Validate",(('Demand Base Matrix'!G$2+'Demand Base Matrix'!G$6)*$AC$2*$AD$2*$AE$2+('Demand Base Matrix'!G$3+'Demand Base Matrix'!G$4)*$W$2*$AD$2+'Demand Base Matrix'!G$5*$W$2*$AD$2*$AE$2+'Demand Base Matrix'!G$7+'Demand Base Matrix'!G$8*$AF$2),IF($C2="Integrate",(('Demand Base Matrix'!G$28+'Demand Base Matrix'!G$32)*$AC$2*$AD$2*$AE$2+('Demand Base Matrix'!G$29+'Demand Base Matrix'!G$30)*$W$2*$AD$2+'Demand Base Matrix'!G$31*$W$2*$AD$2*$AE$2+'Demand Base Matrix'!G$33+'Demand Base Matrix'!G$34*$AF$2),IF($C2="Bond",(('Demand Base Matrix'!G$55+'Demand Base Matrix'!G$59)*$AC$2*$AD$2*$AE$2+('Demand Base Matrix'!G$56+'Demand Base Matrix'!G$57)*$W$2*$AD$2+'Demand Base Matrix'!G$58*$W$2*$AD$2*$AE$2+'Demand Base Matrix'!G$60+'Demand Base Matrix'!G$61*$AF$2),IF($C2="Explore",('Demand Base Matrix'!G$82*$AC$2*$AD$2*$AE$2*$AF$2+'Demand Base Matrix'!G$83*$W$2*$AC$2*$AD$2*$AE$2*$AF$2+'Demand Base Matrix'!G$84))))) -> 50 | AK2: =IF($C2="Validate",(('Demand Base Matrix'!H$2+'Demand Base Matrix'!H$6)*$AC$2*$AD$2*$AE$2+('Demand Base Matrix'!H$3+'Demand Base Matrix'!H$4)*$W$2*$AD$2+'Demand Base Matrix'!H$5*$W$2*$AD$2*$AE$2+'Demand Base Matrix'!H$7+'Demand Base Matrix'!H$8*$AF$2),IF($C2="Integrate",(('Demand Base Matrix'!H$28+'Demand Base Matrix'!H$32)*$AC$2*$AD$2*$AE$2+('Demand Base Matrix'!H$29+'Demand Base Matrix'!H$30)*$W$2*$AD$2+'Demand Base Matrix'!H$31*$W$2*$AD$2*$AE$2+'Demand Base Matrix'!H$33+'Demand Base Matrix'!H$34*$AF$2),IF($C2="Bond",(('Demand Base Matrix'!H$55+'Demand Base Matrix'!H$59)*$AC$2*$AD$2*$AE$2+('Demand Base Matrix'!H$56+'Demand Base Matrix'!H$57)*$W$2*$AD$2+'Demand Base Matrix'!H$58*$W$2*$AD$2*$AE$2+'Demand Base Matrix'!H$60+'Demand Base Matrix'!H$61*$AF$2),IF($C2="Explore",('Demand Base Matrix'!H$82*$AC$2*$AD$2*$AE$2*$AF$2+'Demand Base Matrix'!H$83*$W$2*$AC$2*$AD$2*$AE$2*$AF$2+'Demand Base Matrix'!H$84))))) -> 28 | AL2: =IF($C2="Validate",(('Demand Base Matrix'!I$2+'Demand Base Matrix'!I$6)*$AC$2*$AD$2*$AE$2+('Demand Base Matrix'!I$3+'Demand Base Matrix'!I$4)*$W$2*$AD$2+'Demand Base Matrix'!I$5*$W$2*$AD$2*$AE$2+'Demand Base Matrix'!I$7+'Demand Base Matrix'!I$8*$AF$2),IF($C2="Integrate",(('Demand Base Matrix'!I$28+'Demand Base Matrix'!I$32)*$AC$2*$AD$2*$AE$2+('Demand Base Matrix'!I$29+'Demand Base Matrix'!I$30)*$W$2*$AD$2+'Demand Base Matrix'!I$31*$W$2*$AD$2*$AE$2+'Demand Base Matrix'!I$33+'Demand Base Matrix'!I$34*$AF$2),IF($C2="Bond",(('Demand Base Matrix'!I$55+'Demand Base Matrix'!I$59)*$AC$2*$AD$2*$AE$2+('Demand Base Matrix'!I$56+'Demand Base Matrix'!I$57)*$W$2*$AD$2+'Demand Base Matrix'!I$58*$W$2*$AD$2*$AE$2+'Demand Base Matrix'!I$60+'Demand Base Matrix'!I$61*$AF$2),IF($C2="Explore",('Demand Base Matrix'!I$82*$AC$2*$AD$2*$AE$2*$AF$2+'Demand Base Matrix'!I$83*$W$2*$AC$2*$AD$2*$AE$2*$AF$2+'Demand Base Matrix'!I$84))))) -> 8 | AM2: =IF($C2="Validate",(('Demand Base Matrix'!J$2+'Demand Base Matrix'!J$6)*$AC$2*$AD$2*$AE$2+('Demand Base Matrix'!J$3+'Demand Base Matrix'!J$4)*$W$2*$AD$2+'Demand Base Matrix'!J$5*$W$2*$AD$2*$AE$2+'Demand Base Matrix'!J$7+'Demand Base Matrix'!J$8*$AF$2),IF($C2="Integrate",(('Demand Base Matrix'!J$28+'Demand Base Matrix'!J$32)*$AC$2*$AD$2*$AE$2+('Demand Base Matrix'!J$29+'Demand Base Matrix'!J$30)*$W$2*$AD$2+'Demand Base Matrix'!J$31*$W$2*$AD$2*$AE$2+'Demand Base Matrix'!J$33+'Demand Base Matrix'!J$34*$AF$2),IF($C2="Bond",(('Demand Base Matrix'!J$55+'Demand Base Matrix'!J$59)*$AC$2*$AD$2*$AE$2+('Demand Base Matrix'!J$56+'Demand Base Matrix'!J$57)*$W$2*$AD$2+'Demand Base Matrix'!J$58*$W$2*$AD$2*$AE$2+'Demand Base Matrix'!J$60+'Demand Base Matrix'!J$61*$AF$2),IF($C2="Explore",('Demand Base Matrix'!J$82*$AC$2*$AD$2*$AE$2*$AF$2+'Demand Base Matrix'!J$83*$W$2*$AC$2*$AD$2*$AE$2*$AF$2+'Demand Base Matrix'!J$84))))) -> 8
A3: [2026 [SaaS Y3] Alabama Power - Dx | B3: Alabama Power Company | C3: Bond | D3: Chiranjiv Kathuria | E3: Mannat Padha | F3: Kshitiz Agrawal | I3: =IFERROR(INDEX('Customer 360'!F:F,MATCH(B3,'Customer 360'!A:A,0)),"-") -> A | J3: 52000 | L3: 46295 | M3: 46295 | N3: 2026 | O3: 46023 | P3: IVMS | Q3: =O3 -> 46023 | R3: =IFERROR(IF(M3<>"",M3,IF(L3<>"",L3,INDEX('CSM RDD'!B:B,MATCH(B3,'CSM RDD'!A:A,0)))),"-") -> 46295 | S3: =IFERROR(EOMONTH(Q3,-1)+1,"") -> 46023 | T3: =IFERROR(EOMONTH(R3,-1)+1,"") -> 46266 | U3: =J3+K3 -> 52000 | V3: =IF(C3<>"Validate",DATE(2026,3,1),O3) -> 46082 | W3: =IF(U3=0,1,IF(U3<='Demand Base Matrix'!$K$3,'Demand Base Matrix'!$L$3,IF(U3<='Demand Base Matrix'!$K$4,'Demand Base Matrix'!$L$4,IF(U3<='Demand Base Matrix'!$K$5,'Demand Base Matrix'!$L$5,IF(U3<='Demand Base Matrix'!$K$6,'Demand Base Matrix'!$L$6,IF(U3<='Demand Base Matrix'!$K$7,'Demand Base Matrix'!$L$7)))))) -> 2 | X3: =DATE(YEAR(R3),MONTH(R3),1) -> 46266 | Y3: =IF(K3>0,"Tx","Dx") -> Dx | Z3: Low | AA3: Low | AB3: Medium | AC3: =IFERROR(INDEX('Demand Base Matrix'!AM:AM,MATCH(Y3,'Demand Base Matrix'!AL:AL,0)),"-") -> 1 | AD3: =IFERROR(INDEX('Demand Base Matrix'!AO:AO,MATCH(Z3,'Demand Base Matrix'!AN:AN,0)),1) -> 1 | AE3: =IFERROR(INDEX('Demand Base Matrix'!AQ:AQ,MATCH(AA3,'Demand Base Matrix'!AP:AP,0)),1) -> 1 | AF3: =IFERROR(INDEX('Demand Base Matrix'!AS:AS,MATCH(AB3,'Demand Base Matrix'!AR:AR,0)),1) -> 1.5 | AG3: =IF($C3="Validate",(('Demand Base Matrix'!D$2+'Demand Base Matrix'!D$6)*$AC$2*$AD$2*$AE$2+('Demand Base Matrix'!D$3+'Demand Base Matrix'!D$4)*$W$2*$AD$2+'Demand Base Matrix'!D$5*$W$2*$AD$2*$AE$2+'Demand Base Matrix'!D$7+'Demand Base Matrix'!D$8*$AF$2),IF($C3="Integrate",(('Demand Base Matrix'!D$28+'Demand Base Matrix'!D$32)*$AC$2*$AD$2*$AE$2+('Demand Base Matrix'!D$29+'Demand Base Matrix'!D$30)*$W$2*$AD$2+'Demand Base Matrix'!D$31*$W$2*$AD$2*$AE$2+'Demand Base Matrix'!D$33+'Demand Base Matrix'!D$34*$AF$2),IF($C3="Bond",(('Demand Base Matrix'!D$55+'Demand Base Matrix'!D$59)*$AC$2*$AD$2*$AE$2+('Demand Base Matrix'!D$56+'Demand Base Matrix'!D$57)*$W$2*$AD$2+'Demand Base Matrix'!D$58*$W$2*$AD$2*$AE$2+'Demand Base Matrix'!D$60+'Demand Base Matrix'!D$61*$AF$2),IF($C3="Explore",('Demand Base Matrix'!D$82*$AC$2*$AD$2*$AE$2*$AF$2+'Demand Base Matrix'!D$83*$W$2*$AC$2*$AD$2*$AE$2*$AF$2+'Demand Base Matrix'!D$84))))) -> 10 | AH3: =IF($C3="Validate",(('Demand Base Matrix'!E$2+'Demand Base Matrix'!E$6)*$AC$2*$AD$2*$AE$2+('Demand Base Matrix'!E$3+'Demand Base Matrix'!E$4)*$W$2*$AD$2+'Demand Base Matrix'!E$5*$W$2*$AD$2*$AE$2+'Demand Base Matrix'!E$7+'Demand Base Matrix'!E$8*$AF$2),IF($C3="Integrate",(('Demand Base Matrix'!E$28+'Demand Base Matrix'!E$32)*$AC$2*$AD$2*$AE$2+('Demand Base Matrix'!E$29+'Demand Base Matrix'!E$30)*$W$2*$AD$2+'Demand Base Matrix'!E$31*$W$2*$AD$2*$AE$2+'Demand Base Matrix'!E$33+'Demand Base Matrix'!E$34*$AF$2),IF($C3="Bond",(('Demand Base Matrix'!E$55+'Demand Base Matrix'!E$59)*$AC$2*$AD$2*$AE$2+('Demand Base Matrix'!E$56+'Demand Base Matrix'!E$57)*$W$2*$AD$2+'Demand Base Matrix'!E$58*$W$2*$AD$2*$AE$2+'Demand Base Matrix'!E$60+'Demand Base Matrix'!E$61*$AF$2),IF($C3="Explore",('Demand Base Matrix'!E$82*$AC$2*$AD$2*$AE$2*$AF$2+'Demand Base Matrix'!E$83*$W$2*$AC$2*$AD$2*$AE$2*$AF$2+'Demand Base Matrix'!E$84))))) -> 10 | AI3: =IF($C3="Validate",(('Demand Base Matrix'!F$2+'Demand Base Matrix'!F$6)*$AC$2*$AD$2*$AE$2+('Demand Base Matrix'!F$3+'Demand Base Matrix'!F$4)*$W$2*$AD$2+'Demand Base Matrix'!F$5*$W$2*$AD$2*$AE$2+'Demand Base Matrix'!F$7+'Demand Base Matrix'!F$8*$AF$2),IF($C3="Integrate",(('Demand Base Matrix'!F$28+'Demand Base Matrix'!F$32)*$AC$2*$AD$2*$AE$2+('Demand Base Matrix'!F$29+'Demand Base Matrix'!F$30)*$W$2*$AD$2+'Demand Base Matrix'!F$31*$W$2*$AD$2*$AE$2+'Demand Base Matrix'!F$33+'Demand Base Matrix'!F$34*$AF$2),IF($C3="Bond",(('Demand Base Matrix'!F$55+'Demand Base Matrix'!F$59)*$AC$2*$AD$2*$AE$2+('Demand Base Matrix'!F$56+'Demand Base Matrix'!F$57)*$W$2*$AD$2+'Demand Base Matrix'!F$58*$W$2*$AD$2*$AE$2+'Demand Base Matrix'!F$60+'Demand Base Matrix'!F$61*$AF$2),IF($C3="Explore",('Demand Base Matrix'!F$82*$AC$2*$AD$2*$AE$2*$AF$2+'Demand Base Matrix'!F$83*$W$2*$AC$2*$AD$2*$AE$2*$AF$2+'Demand Base Matrix'!F$84))))) -> 10 | AJ3: =IF($C3="Validate",(('Demand Base Matrix'!G$2+'Demand Base Matrix'!G$6)*$AC$2*$AD$2*$AE$2+('Demand Base Matrix'!G$3+'Demand Base Matrix'!G$4)*$W$2*$AD$2+'Demand Base Matrix'!G$5*$W$2*$AD$2*$AE$2+'Demand Base Matrix'!G$7+'Demand Base Matrix'!G$8*$AF$2),IF($C3="Integrate",(('Demand Base Matrix'!G$28+'Demand Base Matrix'!G$32)*$AC$2*$AD$2*$AE$2+('Demand Base Matrix'!G$29+'Demand Base Matrix'!G$30)*$W$2*$AD$2+'Demand Base Matrix'!G$31*$W$2*$AD$2*$AE$2+'Demand Base Matrix'!G$33+'Demand Base Matrix'!G$34*$AF$2),IF($C3="Bond",(('Demand Base Matrix'!G$55+'Demand Base Matrix'!G$59)*$AC$2*$AD$2*$AE$2+('Demand Base Matrix'!G$56+'Demand Base Matrix'!G$57)*$W$2*$AD$2+'Demand Base Matrix'!G$58*$W$2*$AD$2*$AE$2+'Demand Base Matrix'!G$60+'Demand Base Matrix'!G$61*$AF$2),IF($C3="Explore",('Demand Base Matrix'!G$82*$AC$2*$AD$2*$AE$2*$AF$2+'Demand Base Matrix'!G$83*$W$2*$AC$2*$AD$2*$AE$2*$AF$2+'Demand Base Matrix'!G$84))))) -> 50 | AK3: =IF($C3="Validate",(('Demand Base Matrix'!H$2+'Demand Base Matrix'!H$6)*$AC$2*$AD$2*$AE$2+('Demand Base Matrix'!H$3+'Demand Base Matrix'!H$4)*$W$2*$AD$2+'Demand Base Matrix'!H$5*$W$2*$AD$2*$AE$2+'Demand Base Matrix'!H$7+'Demand Base Matrix'!H$8*$AF$2),IF($C3="Integrate",(('Demand Base Matrix'!H$28+'Demand Base Matrix'!H$32)*$AC$2*$AD$2*$AE$2+('Demand Base Matrix'!H$29+'Demand Base Matrix'!H$30)*$W$2*$AD$2+'Demand Base Matrix'!H$31*$W$2*$AD$2*$AE$2+'Demand Base Matrix'!H$33+'Demand Base Matrix'!H$34*$AF$2),IF($C3="Bond",(('Demand Base Matrix'!H$55+'Demand Base Matrix'!H$59)*$AC$2*$AD$2*$AE$2+('Demand Base Matrix'!H$56+'Demand Base Matrix'!H$57)*$W$2*$AD$2+'Demand Base Matrix'!H$58*$W$2*$AD$2*$AE$2+'Demand Base Matrix'!H$60+'Demand Base Matrix'!H$61*$AF$2),IF($C3="Explore",('Demand Base Matrix'!H$82*$AC$2*$AD$2*$AE$2*$AF$2+'Demand Base Matrix'!H$83*$W$2*$AC$2*$AD$2*$AE$2*$AF$2+'Demand Base Matrix'!H$84))))) -> 28 | AL3: =IF($C3="Validate",(('Demand Base Matrix'!I$2+'Demand Base Matrix'!I$6)*$AC$2*$AD$2*$AE$2+('Demand Base Matrix'!I$3+'Demand Base Matrix'!I$4)*$W$2*$AD$2+'Demand Base Matrix'!I$5*$W$2*$AD$2*$AE$2+'Demand Base Matrix'!I$7+'Demand Base Matrix'!I$8*$AF$2),IF($C3="Integrate",(('Demand Base Matrix'!I$28+'Demand Base Matrix'!I$32)*$AC$2*$AD$2*$AE$2+('Demand Base Matrix'!I$29+'Demand Base Matrix'!I$30)*$W$2*$AD$2+'Demand Base Matrix'!I$31*$W$2*$AD$2*$AE$2+'Demand Base Matrix'!I$33+'Demand Base Matrix'!I$34*$AF$2),IF($C3="Bond",(('Demand Base Matrix'!I$55+'Demand Base Matrix'!I$59)*$AC$2*$AD$2*$AE$2+('Demand Base Matrix'!I$56+'Demand Base Matrix'!I$57)*$W$2*$AD$2+'Demand Base Matrix'!I$58*$W$2*$AD$2*$AE$2+'Demand Base Matrix'!I$60+'Demand Base Matrix'!I$61*$AF$2),IF($C3="Explore",('Demand Base Matrix'!I$82*$AC$2*$AD$2*$AE$2*$AF$2+'Demand Base Matrix'!I$83*$W$2*$AC$2*$AD$2*$AE$2*$AF$2+'Demand Base Matrix'!I$84))))) -> 8 | AM3: =IF($C3="Validate",(('Demand Base Matrix'!J$2+'Demand Base Matrix'!J$6)*$AC$2*$AD$2*$AE$2+('Demand Base Matrix'!J$3+'Demand Base Matrix'!J$4)*$W$2*$AD$2+'Demand Base Matrix'!J$5*$W$2*$AD$2*$AE$2+'Demand Base Matrix'!J$7+'Demand Base Matrix'!J$8*$AF$2),IF($C3="Integrate",(('Demand Base Matrix'!J$28+'Demand Base Matrix'!J$32)*$AC$2*$AD$2*$AE$2+('Demand Base Matrix'!J$29+'Demand Base Matrix'!J$30)*$W$2*$AD$2+'Demand Base Matrix'!J$31*$W$2*$AD$2*$AE$2+'Demand Base Matrix'!J$33+'Demand Base Matrix'!J$34*$AF$2),IF($C3="Bond",(('Demand Base Matrix'!J$55+'Demand Base Matrix'!J$59)*$AC$2*$AD$2*$AE$2+('Demand Base Matrix'!J$56+'Demand Base Matrix'!J$57)*$W$2*$AD$2+'Demand Base Matrix'!J$58*$W$2*$AD$2*$AE$2+'Demand Base Matrix'!J$60+'Demand Base Matrix'!J$61*$AF$2),IF($C3="Explore",('Demand Base Matrix'!J$82*$AC$2*$AD$2*$AE$2*$AF$2+'Demand Base Matrix'!J$83*$W$2*$AC$2*$AD$2*$AE$2*$AF$2+'Demand Base Matrix'!J$84))))) -> 8
A4: [2026 [SaaS Y3] Alabama Power - SubTx | B4: Alabama Power Company | C4: Bond | D4: Chiranjiv Kathuria | E4: Mannat Padha | F4: Kshitiz Agrawal | I4: =IFERROR(INDEX('Customer 360'!F:F,MATCH(B4,'Customer 360'!A:A,0)),"-") -> A | K4: 3298 | L4: 46295 | M4: 46295 | N4: 2026 | O4: 46023 | P4: IVMS | Q4: =O4 -> 46023 | R4: =IFERROR(IF(M4<>"",M4,IF(L4<>"",L4,INDEX('CSM RDD'!B:B,MATCH(B4,'CSM RDD'!A:A,0)))),"-") -> 46295 | S4: =IFERROR(EOMONTH(Q4,-1)+1,"") -> 46023 | T4: =IFERROR(EOMONTH(R4,-1)+1,"") -> 46266 | U4: =J4+K4 -> 3298 | V4: =IF(C4<>"Validate",DATE(2026,3,1),O4) -> 46082 | W4: =IF(U4=0,1,IF(U4<='Demand Base Matrix'!$K$3,'Demand Base Matrix'!$L$3,IF(U4<='Demand Base Matrix'!$K$4,'Demand Base Matrix'!$L$4,IF(U4<='Demand Base Matrix'!$K$5,'Demand Base Matrix'!$L$5,IF(U4<='Demand Base Matrix'!$K$6,'Demand Base Matrix'!$L$6,IF(U4<='Demand Base Matrix'!$K$7,'Demand Base Matrix'!$L$7)))))) -> 1 | X4: =DATE(YEAR(R4),MONTH(R4),1) -> 46266 | Y4: =IF(K4>0,"Tx","Dx") -> Tx | Z4: Low | AA4: Low | AB4: Medium | AC4: =IFERROR(INDEX('Demand Base Matrix'!AM:AM,MATCH(Y4,'Demand Base Matrix'!AL:AL,0)),"-") -> 1.5 | AD4: =IFERROR(INDEX('Demand Base Matrix'!AO:AO,MATCH(Z4,'Demand Base Matrix'!AN:AN,0)),1) -> 1 | AE4: =IFERROR(INDEX('Demand Base Matrix'!AQ:AQ,MATCH(AA4,'Demand Base Matrix'!AP:AP,0)),1) -> 1 | AF4: =IFERROR(INDEX('Demand Base Matrix'!AS:AS,MATCH(AB4,'Demand Base Matrix'!AR:AR,0)),1) -> 1.5 | AG4: =IF($C4="Validate",(('Demand Base Matrix'!D$2+'Demand Base Matrix'!D$6)*$AC$2*$AD$2*$AE$2+('Demand Base Matrix'!D$3+'Demand Base Matrix'!D$4)*$W$2*$AD$2+'Demand Base Matrix'!D$5*$W$2*$AD$2*$AE$2+'Demand Base Matrix'!D$7+'Demand Base Matrix'!D$8*$AF$2),IF($C4="Integrate",(('Demand Base Matrix'!D$28+'Demand Base Matrix'!D$32)*$AC$2*$AD$2*$AE$2+('Demand Base Matrix'!D$29+'Demand Base Matrix'!D$30)*$W$2*$AD$2+'Demand Base Matrix'!D$31*$W$2*$AD$2*$AE$2+'Demand Base Matrix'!D$33+'Demand Base Matrix'!D$34*$AF$2),IF($C4="Bond",(('Demand Base Matrix'!D$55+'Demand Base Matrix'!D$59)*$AC$2*$AD$2*$AE$2+('Demand Base Matrix'!D$56+'Demand Base Matrix'!D$57)*$W$2*$AD$2+'Demand Base Matrix'!D$58*$W$2*$AD$2*$AE$2+'Demand Base Matrix'!D$60+'Demand Base Matrix'!D$61*$AF$2),IF($C4="Explore",('Demand Base Matrix'!D$82*$AC$2*$AD$2*$AE$2*$AF$2+'Demand Base Matrix'!D$83*$W$2*$AC$2*$AD$2*$AE$2*$AF$2+'Demand Base Matrix'!D$84))))) -> 10 | AH4: =IF($C4="Validate",(('Demand Base Matrix'!E$2+'Demand Base Matrix'!E$6)*$AC$2*$AD$2*$AE$2+('Demand Base Matrix'!E$3+'Demand Base Matrix'!E$4)*$W$2*$AD$2+'Demand Base Matrix'!E$5*$W$2*$AD$2*$AE$2+'Demand Base Matrix'!E$7+'Demand Base Matrix'!E$8*$AF$2),IF($C4="Integrate",(('Demand Base Matrix'!E$28+'Demand Base Matrix'!E$32)*$AC$2*$AD$2*$AE$2+('Demand Base Matrix'!E$29+'Demand Base Matrix'!E$30)*$W$2*$AD$2+'Demand Base Matrix'!E$31*$W$2*$AD$2*$AE$2+'Demand Base Matrix'!E$33+'Demand Base Matrix'!E$34*$AF$2),IF($C4="Bond",(('Demand Base Matrix'!E$55+'Demand Base Matrix'!E$59)*$AC$2*$AD$2*$AE$2+('Demand Base Matrix'!E$56+'Demand Base Matrix'!E$57)*$W$2*$AD$2+'Demand Base Matrix'!E$58*$W$2*$AD$2*$AE$2+'Demand Base Matrix'!E$60+'Demand Base Matrix'!E$61*$AF$2),IF($C4="Explore",('Demand Base Matrix'!E$82*$AC$2*$AD$2*$AE$2*$AF$2+'Demand Base Matrix'!E$83*$W$2*$AC$2*$AD$2*$AE$2*$AF$2+'Demand Base Matrix'!E$84))))) -> 10 | AI4: =IF($C4="Validate",(('Demand Base Matrix'!F$2+'Demand Base Matrix'!F$6)*$AC$2*$AD$2*$AE$2+('Demand Base Matrix'!F$3+'Demand Base Matrix'!F$4)*$W$2*$AD$2+'Demand Base Matrix'!F$5*$W$2*$AD$2*$AE$2+'Demand Base Matrix'!F$7+'Demand Base Matrix'!F$8*$AF$2),IF($C4="Integrate",(('Demand Base Matrix'!F$28+'Demand Base Matrix'!F$32)*$AC$2*$AD$2*$AE$2+('Demand Base Matrix'!F$29+'Demand Base Matrix'!F$30)*$W$2*$AD$2+'Demand Base Matrix'!F$31*$W$2*$AD$2*$AE$2+'Demand Base Matrix'!F$33+'Demand Base Matrix'!F$34*$AF$2),IF($C4="Bond",(('Demand Base Matrix'!F$55+'Demand Base Matrix'!F$59)*$AC$2*$AD$2*$AE$2+('Demand Base Matrix'!F$56+'Demand Base Matrix'!F$57)*$W$2*$AD$2+'Demand Base Matrix'!F$58*$W$2*$AD$2*$AE$2+'Demand Base Matrix'!F$60+'Demand Base Matrix'!F$61*$AF$2),IF($C4="Explore",('Demand Base Matrix'!F$82*$AC$2*$AD$2*$AE$2*$AF$2+'Demand Base Matrix'!F$83*$W$2*$AC$2*$AD$2*$AE$2*$AF$2+'Demand Base Matrix'!F$84))))) -> 10 | AJ4: =IF($C4="Validate",(('Demand Base Matrix'!G$2+'Demand Base Matrix'!G$6)*$AC$2*$AD$2*$AE$2+('Demand Base Matrix'!G$3+'Demand Base Matrix'!G$4)*$W$2*$AD$2+'Demand Base Matrix'!G$5*$W$2*$AD$2*$AE$2+'Demand Base Matrix'!G$7+'Demand Base Matrix'!G$8*$AF$2),IF($C4="Integrate",(('Demand Base Matrix'!G$28+'Demand Base Matrix'!G$32)*$AC$2*$AD$2*$AE$2+('Demand Base Matrix'!G$29+'Demand Base Matrix'!G$30)*$W$2*$AD$2+'Demand Base Matrix'!G$31*$W$2*$AD$2*$AE$2+'Demand Base Matrix'!G$33+'Demand Base Matrix'!G$34*$AF$2),IF($C4="Bond",(('Demand Base Matrix'!G$55+'Demand Base Matrix'!G$59)*$AC$2*$AD$2*$AE$2+('Demand Base Matrix'!G$56+'Demand Base Matrix'!G$57)*$W$2*$AD$2+'Demand Base Matrix'!G$58*$W$2*$AD$2*$AE$2+'Demand Base Matrix'!G$60+'Demand Base Matrix'!G$61*$AF$2),IF($C4="Explore",('Demand Base Matrix'!G$82*$AC$2*$AD$2*$AE$2*$AF$2+'Demand Base Matrix'!G$83*$W$2*$AC$2*$AD$2*$AE$2*$AF$2+'Demand Base Matrix'!G$84))))) -> 50 | AK4: =IF($C4="Validate",(('Demand Base Matrix'!H$2+'Demand Base Matrix'!H$6)*$AC$2*$AD$2*$AE$2+('Demand Base Matrix'!H$3+'Demand Base Matrix'!H$4)*$W$2*$AD$2+'Demand Base Matrix'!H$5*$W$2*$AD$2*$AE$2+'Demand Base Matrix'!H$7+'Demand Base Matrix'!H$8*$AF$2),IF($C4="Integrate",(('Demand Base Matrix'!H$28+'Demand Base Matrix'!H$32)*$AC$2*$AD$2*$AE$2+('Demand Base Matrix'!H$29+'Demand Base Matrix'!H$30)*$W$2*$AD$2+'Demand Base Matrix'!H$31*$W$2*$AD$2*$AE$2+'Demand Base Matrix'!H$33+'Demand Base Matrix'!H$34*$AF$2),IF($C4="Bond",(('Demand Base Matrix'!H$55+'Demand Base Matrix'!H$59)*$AC$2*$AD$2*$AE$2+('Demand Base Matrix'!H$56+'Demand Base Matrix'!H$57)*$W$2*$AD$2+'Demand Base Matrix'!H$58*$W$2*$AD$2*$AE$2+'Demand Base Matrix'!H$60+'Demand Base Matrix'!H$61*$AF$2),IF($C4="Explore",('Demand Base Matrix'!H$82*$AC$2*$AD$2*$AE$2*$AF$2+'Demand Base Matrix'!H$83*$W$2*$AC$2*$AD$2*$AE$2*$AF$2+'Demand Base Matrix'!H$84))))) -> 28 | AL4: =IF($C4="Validate",(('Demand Base Matrix'!I$2+'Demand Base Matrix'!I$6)*$AC$2*$AD$2*$AE$2+('Demand Base Matrix'!I$3+'Demand Base Matrix'!I$4)*$W$2*$AD$2+'Demand Base Matrix'!I$5*$W$2*$AD$2*$AE$2+'Demand Base Matrix'!I$7+'Demand Base Matrix'!I$8*$AF$2),IF($C4="Integrate",(('Demand Base Matrix'!I$28+'Demand Base Matrix'!I$32)*$AC$2*$AD$2*$AE$2+('Demand Base Matrix'!I$29+'Demand Base Matrix'!I$30)*$W$2*$AD$2+'Demand Base Matrix'!I$31*$W$2*$AD$2*$AE$2+'Demand Base Matrix'!I$33+'Demand Base Matrix'!I$34*$AF$2),IF($C4="Bond",(('Demand Base Matrix'!I$55+'Demand Base Matrix'!I$59)*$AC$2*$AD$2*$AE$2+('Demand Base Matrix'!I$56+'Demand Base Matrix'!I$57)*$W$2*$AD$2+'Demand Base Matrix'!I$58*$W$2*$AD$2*$AE$2+'Demand Base Matrix'!I$60+'Demand Base Matrix'!I$61*$AF$2),IF($C4="Explore",('Demand Base Matrix'!I$82*$AC$2*$AD$2*$AE$2*$AF$2+'Demand Base Matrix'!I$83*$W$2*$AC$2*$AD$2*$AE$2*$AF$2+'Demand Base Matrix'!I$84))))) -> 8 | AM4: =IF($C4="Validate",(('Demand Base Matrix'!J$2+'Demand Base Matrix'!J$6)*$AC$2*$AD$2*$AE$2+('Demand Base Matrix'!J$3+'Demand Base Matrix'!J$4)*$W$2*$AD$2+'Demand Base Matrix'!J$5*$W$2*$AD$2*$AE$2+'Demand Base Matrix'!J$7+'Demand Base Matrix'!J$8*$AF$2),IF($C4="Integrate",(('Demand Base Matrix'!J$28+'Demand Base Matrix'!J$32)*$AC$2*$AD$2*$AE$2+('Demand Base Matrix'!J$29+'Demand Base Matrix'!J$30)*$W$2*$AD$2+'Demand Base Matrix'!J$31*$W$2*$AD$2*$AE$2+'Demand Base Matrix'!J$33+'Demand Base Matrix'!J$34*$AF$2),IF($C4="Bond",(('Demand Base Matrix'!J$55+'Demand Base Matrix'!J$59)*$AC$2*$AD$2*$AE$2+('Demand Base Matrix'!J$56+'Demand Base Matrix'!J$57)*$W$2*$AD$2+'Demand Base Matrix'!J$58*$W$2*$AD$2*$AE$2+'Demand Base Matrix'!J$60+'Demand Base Matrix'!J$61*$AF$2),IF($C4="Explore",('Demand Base Matrix'!J$82*$AC$2*$AD$2*$AE$2*$AF$2+'Demand Base Matrix'!J$83*$W$2*$AC$2*$AD$2*$AE$2*$AF$2+'Demand Base Matrix'!J$84))))) -> 8
A5: [2025 SaaS Y1] Arizona Public Service | B5: Arizona Public Service | C5: Validate | D5: Jessica Felde | E5: Mukul Mathur | F5: Piyush Kumar Pandey | I5: =IFERROR(INDEX('Customer 360'!F:F,MATCH(B5,'Customer 360'!A:A,0)),"-") -> A | J5: 68 | K5: 23 | L5: 46216 | M5: 46216 | N5: 2025 | O5: 46082 | P5: IVMS | Q5: =O5 -> 46082 | R5: =IFERROR(IF(M5<>"",M5,IF(L5<>"",L5,INDEX('CSM RDD'!B:B,MATCH(B5,'CSM RDD'!A:A,0)))),"-") -> 46216 | S5: =IFERROR(EOMONTH(Q5,-1)+1,"") -> 46082 | T5: =IFERROR(EOMONTH(R5,-1)+1,"") -> 46204 | U5: =J5+K5 -> 91 | V5: =IF(C5<>"Validate",DATE(2026,3,1),O5) -> 46082 | W5: =IF(U5=0,1,IF(U5<='Demand Base Matrix'!$K$3,'Demand Base Matrix'!$L$3,IF(U5<='Demand Base Matrix'!$K$4,'Demand Base Matrix'!$L$4,IF(U5<='Demand Base Matrix'!$K$5,'Demand Base Matrix'!$L$5,IF(U5<='Demand Base Matrix'!$K$6,'Demand Base Matrix'!$L$6,IF(U5<='Demand Base Matrix'!$K$7,'Demand Base Matrix'!$L$7)))))) -> 0.75 | X5: =DATE(YEAR(R5),MONTH(R5),1) -> 46204 | Y5: =IF(K5>0,"Tx","Dx") -> Tx | Z5: Low | AA5: Low | AB5: Low | AC5: =IFERROR(INDEX('Demand Base Matrix'!AM:AM,MATCH(Y5,'Demand Base Matrix'!AL:AL,0)),"-") -> 1.5 | AD5: =IFERROR(INDEX('Demand Base Matrix'!AO:AO,MATCH(Z5,'Demand Base Matrix'!AN:AN,0)),1) -> 1 | AE5: =IFERROR(INDEX('Demand Base Matrix'!AQ:AQ,MATCH(AA5,'Demand Base Matrix'!AP:AP,0)),1) -> 1 | AF5: =IFERROR(INDEX('Demand Base Matrix'!AS:AS,MATCH(AB5,'Demand Base Matrix'!AR:AR,0)),1) -> 1 | AG5: =IF($C5="Validate",(('Demand Base Matrix'!D$2+'Demand Base Matrix'!D$6)*$AC$2*$AD$2*$AE$2+('Demand Base Matrix'!D$3+'Demand Base Matrix'!D$4)*$W$2*$AD$2+'Demand Base Matrix'!D$5*$W$2*$AD$2*$AE$2+'Demand Base Matrix'!D$7+'Demand Base Matrix'!D$8*$AF$2),IF($C5="Integrate",(('Demand Base Matrix'!D$28+'Demand Base Matrix'!D$32)*$AC$2*$AD$2*$AE$2+('Demand Base Matrix'!D$29+'Demand Base Matrix'!D$30)*$W$2*$AD$2+'Demand Base Matrix'!D$31*$W$2*$AD$2*$AE$2+'Demand Base Matrix'!D$33+'Demand Base Matrix'!D$34*$AF$2),IF($C5="Bond",(('Demand Base Matrix'!D$55+'Demand Base Matrix'!D$59)*$AC$2*$AD$2*$AE$2+('Demand Base Matrix'!D$56+'Demand Base Matrix'!D$57)*$W$2*$AD$2+'Demand Base Matrix'!D$58*$W$2*$AD$2*$AE$2+'Demand Base Matrix'!D$60+'Demand Base Matrix'!D$61*$AF$2),IF($C5="Explore",('Demand Base Matrix'!D$82*$AC$2*$AD$2*$AE$2*$AF$2+'Demand Base Matrix'!D$83*$W$2*$AC$2*$AD$2*$AE$2*$AF$2+'Demand Base Matrix'!D$84))))) -> 15 | AH5: =IF($C5="Validate",(('Demand Base Matrix'!E$2+'Demand Base Matrix'!E$6)*$AC$2*$AD$2*$AE$2+('Demand Base Matrix'!E$3+'Demand Base Matrix'!E$4)*$W$2*$AD$2+'Demand Base Matrix'!E$5*$W$2*$AD$2*$AE$2+'Demand Base Matrix'!E$7+'Demand Base Matrix'!E$8*$AF$2),IF($C5="Integrate",(('Demand Base Matrix'!E$28+'Demand Base Matrix'!E$32)*$AC$2*$AD$2*$AE$2+('Demand Base Matrix'!E$29+'Demand Base Matrix'!E$30)*$W$2*$AD$2+'Demand Base Matrix'!E$31*$W$2*$AD$2*$AE$2+'Demand Base Matrix'!E$33+'Demand Base Matrix'!E$34*$AF$2),IF($C5="Bond",(('Demand Base Matrix'!E$55+'Demand Base Matrix'!E$59)*$AC$2*$AD$2*$AE$2+('Demand Base Matrix'!E$56+'Demand Base Matrix'!E$57)*$W$2*$AD$2+'Demand Base Matrix'!E$58*$W$2*$AD$2*$AE$2+'Demand Base Matrix'!E$60+'Demand Base Matrix'!E$61*$AF$2),IF($C5="Explore",('Demand Base Matrix'!E$82*$AC$2*$AD$2*$AE$2*$AF$2+'Demand Base Matrix'!E$83*$W$2*$AC$2*$AD$2*$AE$2*$AF$2+'Demand Base Matrix'!E$84))))) -> 15 | AI5: =IF($C5="Validate",(('Demand Base Matrix'!F$2+'Demand Base Matrix'!F$6)*$AC$2*$AD$2*$AE$2+('Demand Base Matrix'!F$3+'Demand Base Matrix'!F$4)*$W$2*$AD$2+'Demand Base Matrix'!F$5*$W$2*$AD$2*$AE$2+'Demand Base Matrix'!F$7+'Demand Base Matrix'!F$8*$AF$2),IF($C5="Integrate",(('Demand Base Matrix'!F$28+'Demand Base Matrix'!F$32)*$AC$2*$AD$2*$AE$2+('Demand Base Matrix'!F$29+'Demand Base Matrix'!F$30)*$W$2*$AD$2+'Demand Base Matrix'!F$31*$W$2*$AD$2*$AE$2+'Demand Base Matrix'!F$33+'Demand Base Matrix'!F$34*$AF$2),IF($C5="Bond",(('Demand Base Matrix'!F$55+'Demand Base Matrix'!F$59)*$AC$2*$AD$2*$AE$2+('Demand Base Matrix'!F$56+'Demand Base Matrix'!F$57)*$W$2*$AD$2+'Demand Base Matrix'!F$58*$W$2*$AD$2*$AE$2+'Demand Base Matrix'!F$60+'Demand Base Matrix'!F$61*$AF$2),IF($C5="Explore",('Demand Base Matrix'!F$82*$AC$2*$AD$2*$AE$2*$AF$2+'Demand Base Matrix'!F$83*$W$2*$AC$2*$AD$2*$AE$2*$AF$2+'Demand Base Matrix'!F$84))))) -> 7 | AJ5: =IF($C5="Validate",(('Demand Base Matrix'!G$2+'Demand Base Matrix'!G$6)*$AC$2*$AD$2*$AE$2+('Demand Base Matrix'!G$3+'Demand Base Matrix'!G$4)*$W$2*$AD$2+'Demand Base Matrix'!G$5*$W$2*$AD$2*$AE$2+'Demand Base Matrix'!G$7+'Demand Base Matrix'!G$8*$AF$2),IF($C5="Integrate",(('Demand Base Matrix'!G$28+'Demand Base Matrix'!G$32)*$AC$2*$AD$2*$AE$2+('Demand Base Matrix'!G$29+'Demand Base Matrix'!G$30)*$W$2*$AD$2+'Demand Base Matrix'!G$31*$W$2*$AD$2*$AE$2+'Demand Base Matrix'!G$33+'Demand Base Matrix'!G$34*$AF$2),IF($C5="Bond",(('Demand Base Matrix'!G$55+'Demand Base Matrix'!G$59)*$AC$2*$AD$2*$AE$2+('Demand Base Matrix'!G$56+'Demand Base Matrix'!G$57)*$W$2*$AD$2+'Demand Base Matrix'!G$58*$W$2*$AD$2*$AE$2+'Demand Base Matrix'!G$60+'Demand Base Matrix'!G$61*$AF$2),IF($C5="Explore",('Demand Base Matrix'!G$82*$AC$2*$AD$2*$AE$2*$AF$2+'Demand Base Matrix'!G$83*$W$2*$AC$2*$AD$2*$AE$2*$AF$2+'Demand Base Matrix'!G$84))))) -> 40 | AK5: =IF($C5="Validate",(('Demand Base Matrix'!H$2+'Demand Base Matrix'!H$6)*$AC$2*$AD$2*$AE$2+('Demand Base Matrix'!H$3+'Demand Base Matrix'!H$4)*$W$2*$AD$2+'Demand Base Matrix'!H$5*$W$2*$AD$2*$AE$2+'Demand Base Matrix'!H$7+'Demand Base Matrix'!H$8*$AF$2),IF($C5="Integrate",(('Demand Base Matrix'!H$28+'Demand Base Matrix'!H$32)*$AC$2*$AD$2*$AE$2+('Demand Base Matrix'!H$29+'Demand Base Matrix'!H$30)*$W$2*$AD$2+'Demand Base Matrix'!H$31*$W$2*$AD$2*$AE$2+'Demand Base Matrix'!H$33+'Demand Base Matrix'!H$34*$AF$2),IF($C5="Bond",(('Demand Base Matrix'!H$55+'Demand Base Matrix'!H$59)*$AC$2*$AD$2*$AE$2+('Demand Base Matrix'!H$56+'Demand Base Matrix'!H$57)*$W$2*$AD$2+'Demand Base Matrix'!H$58*$W$2*$AD$2*$AE$2+'Demand Base Matrix'!H$60+'Demand Base Matrix'!H$61*$AF$2),IF($C5="Explore",('Demand Base Matrix'!H$82*$AC$2*$AD$2*$AE$2*$AF$2+'Demand Base Matrix'!H$83*$W$2*$AC$2*$AD$2*$AE$2*$AF$2+'Demand Base Matrix'!H$84))))) -> 60 | AL5: =IF($C5="Validate",(('Demand Base Matrix'!I$2+'Demand Base Matrix'!I$6)*$AC$2*$AD$2*$AE$2+('Demand Base Matrix'!I$3+'Demand Base Matrix'!I$4)*$W$2*$AD$2+'Demand Base Matrix'!I$5*$W$2*$AD$2*$AE$2+'Demand Base Matrix'!I$7+'Demand Base Matrix'!I$8*$AF$2),IF($C5="Integrate",(('Demand Base Matrix'!I$28+'Demand Base Matrix'!I$32)*$AC$2*$AD$2*$AE$2+('Demand Base Matrix'!I$29+'Demand Base Matrix'!I$30)*$W$2*$AD$2+'Demand Base Matrix'!I$31*$W$2*$AD$2*$AE$2+'Demand Base Matrix'!I$33+'Demand Base Matrix'!I$34*$AF$2),IF($C5="Bond",(('Demand Base Matrix'!I$55+'Demand Base Matrix'!I$59)*$AC$2*$AD$2*$AE$2+('Demand Base Matrix'!I$56+'Demand Base Matrix'!I$57)*$W$2*$AD$2+'Demand Base Matrix'!I$58*$W$2*$AD$2*$AE$2+'Demand Base Matrix'!I$60+'Demand Base Matrix'!I$61*$AF$2),IF($C5="Explore",('Demand Base Matrix'!I$82*$AC$2*$AD$2*$AE$2*$AF$2+'Demand Base Matrix'!I$83*$W$2*$AC$2*$AD$2*$AE$2*$AF$2+'Demand Base Matrix'!I$84))))) -> 10 | AM5: =IF($C5="Validate",(('Demand Base Matrix'!J$2+'Demand Base Matrix'!J$6)*$AC$2*$AD$2*$AE$2+('Demand Base Matrix'!J$3+'Demand Base Matrix'!J$4)*$W$2*$AD$2+'Demand Base Matrix'!J$5*$W$2*$AD$2*$AE$2+'Demand Base Matrix'!J$7+'Demand Base Matrix'!J$8*$AF$2),IF($C5="Integrate",(('Demand Base Matrix'!J$28+'Demand Base Matrix'!J$32)*$AC$2*$AD$2*$AE$2+('Demand Base Matrix'!J$29+'Demand Base Matrix'!J$30)*$W$2*$AD$2+'Demand Base Matrix'!J$31*$W$2*$AD$2*$AE$2+'Demand Base Matrix'!J$33+'Demand Base Matrix'!J$34*$AF$2),IF($C5="Bond",(('Demand Base Matrix'!J$55+'Demand Base Matrix'!J$59)*$AC$2*$AD$2*$AE$2+('Demand Base Matrix'!J$56+'Demand Base Matrix'!J$57)*$W$2*$AD$2+'Demand Base Matrix'!J$58*$W$2*$AD$2*$AE$2+'Demand Base Matrix'!J$60+'Demand Base Matrix'!J$61*$AF$2),IF($C5="Explore",('Demand Base Matrix'!J$82*$AC$2*$AD$2*$AE$2*$AF$2+'Demand Base Matrix'!J$83*$W$2*$AC$2*$AD$2*$AE$2*$AF$2+'Demand Base Matrix'!J$84))))) -> 4
A6: [2026 SaaS Y4] Arkansas Valley | B6: Arkansas Valley Electric Cooperative Corporation | C6: Bond | D6: Savannah Peery | E6: Shashank Sharma | F6: Satyam Kumar | I6: =IFERROR(INDEX('Customer 360'!F:F,MATCH(B6,'Customer 360'!A:A,0)),"-") -> C | J6: 6320 | L6: 46239 | M6: 46239 | N6: 2026 | O6: 46023 | P6: IVMS | Q6: =O6 -> 46023 | R6: =IFERROR(IF(M6<>"",M6,IF(L6<>"",L6,INDEX('CSM RDD'!B:B,MATCH(B6,'CSM RDD'!A:A,0)))),"-") -> 46239 | S6: =IFERROR(EOMONTH(Q6,-1)+1,"") -> 46023 | T6: =IFERROR(EOMONTH(R6,-1)+1,"") -> 46235 | U6: =J6+K6 -> 6320 | V6: =IF(C6<>"Validate",DATE(2026,3,1),O6) -> 46082 | W6: =IF(U6=0,1,IF(U6<='Demand Base Matrix'!$K$3,'Demand Base Matrix'!$L$3,IF(U6<='Demand Base Matrix'!$K$4,'Demand Base Matrix'!$L$4,IF(U6<='Demand Base Matrix'!$K$5,'Demand Base Matrix'!$L$5,IF(U6<='Demand Base Matrix'!$K$6,'Demand Base Matrix'!$L$6,IF(U6<='Demand Base Matrix'!$K$7,'Demand Base Matrix'!$L$7)))))) -> 1.25 | X6: =DATE(YEAR(R6),MONTH(R6),1) -> 46235 | Y6: =IF(K6>0,"Tx","Dx") -> Dx | Z6: Low | AA6: Low | AB6: Low | AC6: =IFERROR(INDEX('Demand Base Matrix'!AM:AM,MATCH(Y6,'Demand Base Matrix'!AL:AL,0)),"-") -> 1 | AD6: =IFERROR(INDEX('Demand Base Matrix'!AO:AO,MATCH(Z6,'Demand Base Matrix'!AN:AN,0)),1) -> 1 | AE6: =IFERROR(INDEX('Demand Base Matrix'!AQ:AQ,MATCH(AA6,'Demand Base Matrix'!AP:AP,0)),1) -> 1 | AF6: =IFERROR(INDEX('Demand Base Matrix'!AS:AS,MATCH(AB6,'Demand Base Matrix'!AR:AR,0)),1) -> 1 | AG6: =IF($C6="Validate",(('Demand Base Matrix'!D$2+'Demand Base Matrix'!D$6)*$AC$2*$AD$2*$AE$2+('Demand Base Matrix'!D$3+'Demand Base Matrix'!D$4)*$W$2*$AD$2+'Demand Base Matrix'!D$5*$W$2*$AD$2*$AE$2+'Demand Base Matrix'!D$7+'Demand Base Matrix'!D$8*$AF$2),IF($C6="Integrate",(('Demand Base Matrix'!D$28+'Demand Base Matrix'!D$32)*$AC$2*$AD$2*$AE$2+('Demand Base Matrix'!D$29+'Demand Base Matrix'!D$30)*$W$2*$AD$2+'Demand Base Matrix'!D$31*$W$2*$AD$2*$AE$2+'Demand Base Matrix'!D$33+'Demand Base Matrix'!D$34*$AF$2),IF($C6="Bond",(('Demand Base Matrix'!D$55+'Demand Base Matrix'!D$59)*$AC$2*$AD$2*$AE$2+('Demand Base Matrix'!D$56+'Demand Base Matrix'!D$57)*$W$2*$AD$2+'Demand Base Matrix'!D$58*$W$2*$AD$2*$AE$2+'Demand Base Matrix'!D$60+'Demand Base Matrix'!D$61*$AF$2),IF($C6="Explore",('Demand Base Matrix'!D$82*$AC$2*$AD$2*$AE$2*$AF$2+'Demand Base Matrix'!D$83*$W$2*$AC$2*$AD$2*$AE$2*$AF$2+'Demand Base Matrix'!D$84))))) -> 10 | AH6: =IF($C6="Validate",(('Demand Base Matrix'!E$2+'Demand Base Matrix'!E$6)*$AC$2*$AD$2*$AE$2+('Demand Base Matrix'!E$3+'Demand Base Matrix'!E$4)*$W$2*$AD$2+'Demand Base Matrix'!E$5*$W$2*$AD$2*$AE$2+'Demand Base Matrix'!E$7+'Demand Base Matrix'!E$8*$AF$2),IF($C6="Integrate",(('Demand Base Matrix'!E$28+'Demand Base Matrix'!E$32)*$AC$2*$AD$2*$AE$2+('Demand Base Matrix'!E$29+'Demand Base Matrix'!E$30)*$W$2*$AD$2+'Demand Base Matrix'!E$31*$W$2*$AD$2*$AE$2+'Demand Base Matrix'!E$33+'Demand Base Matrix'!E$34*$AF$2),IF($C6="Bond",(('Demand Base Matrix'!E$55+'Demand Base Matrix'!E$59)*$AC$2*$AD$2*$AE$2+('Demand Base Matrix'!E$56+'Demand Base Matrix'!E$57)*$W$2*$AD$2+'Demand Base Matrix'!E$58*$W$2*$AD$2*$AE$2+'Demand Base Matrix'!E$60+'Demand Base Matrix'!E$61*$AF$2),IF($C6="Explore",('Demand Base Matrix'!E$82*$AC$2*$AD$2*$AE$2*$AF$2+'Demand Base Matrix'!E$83*$W$2*$AC$2*$AD$2*$AE$2*$AF$2+'Demand Base Matrix'!E$84))))) -> 10 | AI6: =IF($C6="Validate",(('Demand Base Matrix'!F$2+'Demand Base Matrix'!F$6)*$AC$2*$AD$2*$AE$2+('Demand Base Matrix'!F$3+'Demand Base Matrix'!F$4)*$W$2*$AD$2+'Demand Base Matrix'!F$5*$W$2*$AD$2*$AE$2+'Demand Base Matrix'!F$7+'Demand Base Matrix'!F$8*$AF$2),IF($C6="Integrate",(('Demand Base Matrix'!F$28+'Demand Base Matrix'!F$32)*$AC$2*$AD$2*$AE$2+('Demand Base Matrix'!F$29+'Demand Base Matrix'!F$30)*$W$2*$AD$2+'Demand Base Matrix'!F$31*$W$2*$AD$2*$AE$2+'Demand Base Matrix'!F$33+'Demand Base Matrix'!F$34*$AF$2),IF($C6="Bond",(('Demand Base Matrix'!F$55+'Demand Base Matrix'!F$59)*$AC$2*$AD$2*$AE$2+('Demand Base Matrix'!F$56+'Demand Base Matrix'!F$57)*$W$2*$AD$2+'Demand Base Matrix'!F$58*$W$2*$AD$2*$AE$2+'Demand Base Matrix'!F$60+'Demand Base Matrix'!F$61*$AF$2),IF($C6="Explore",('Demand Base Matrix'!F$82*$AC$2*$AD$2*$AE$2*$AF$2+'Demand Base Matrix'!F$83*$W$2*$AC$2*$AD$2*$AE$2*$AF$2+'Demand Base Matrix'!F$84))))) -> 10 | AJ6: =IF($C6="Validate",(('Demand Base Matrix'!G$2+'Demand Base Matrix'!G$6)*$AC$2*$AD$2*$AE$2+('Demand Base Matrix'!G$3+'Demand Base Matrix'!G$4)*$W$2*$AD$2+'Demand Base Matrix'!G$5*$W$2*$AD$2*$AE$2+'Demand Base Matrix'!G$7+'Demand Base Matrix'!G$8*$AF$2),IF($C6="Integrate",(('Demand Base Matrix'!G$28+'Demand Base Matrix'!G$32)*$AC$2*$AD$2*$AE$2+('Demand Base Matrix'!G$29+'Demand Base Matrix'!G$30)*$W$2*$AD$2+'Demand Base Matrix'!G$31*$W$2*$AD$2*$AE$2+'Demand Base Matrix'!G$33+'Demand Base Matrix'!G$34*$AF$2),IF($C6="Bond",(('Demand Base Matrix'!G$55+'Demand Base Matrix'!G$59)*$AC$2*$AD$2*$AE$2+('Demand Base Matrix'!G$56+'Demand Base Matrix'!G$57)*$W$2*$AD$2+'Demand Base Matrix'!G$58*$W$2*$AD$2*$AE$2+'Demand Base Matrix'!G$60+'Demand Base Matrix'!G$61*$AF$2),IF($C6="Explore",('Demand Base Matrix'!G$82*$AC$2*$AD$2*$AE$2*$AF$2+'Demand Base Matrix'!G$83*$W$2*$AC$2*$AD$2*$AE$2*$AF$2+'Demand Base Matrix'!G$84))))) -> 50 | AK6: =IF($C6="Validate",(('Demand Base Matrix'!H$2+'Demand Base Matrix'!H$6)*$AC$2*$AD$2*$AE$2+('Demand Base Matrix'!H$3+'Demand Base Matrix'!H$4)*$W$2*$AD$2+'Demand Base Matrix'!H$5*$W$2*$AD$2*$AE$2+'Demand Base Matrix'!H$7+'Demand Base Matrix'!H$8*$AF$2),IF($C6="Integrate",(('Demand Base Matrix'!H$28+'Demand Base Matrix'!H$32)*$AC$2*$AD$2*$AE$2+('Demand Base Matrix'!H$29+'Demand Base Matrix'!H$30)*$W$2*$AD$2+'Demand Base Matrix'!H$31*$W$2*$AD$2*$AE$2+'Demand Base Matrix'!H$33+'Demand Base Matrix'!H$34*$AF$2),IF($C6="Bond",(('Demand Base Matrix'!H$55+'Demand Base Matrix'!H$59)*$AC$2*$AD$2*$AE$2+('Demand Base Matrix'!H$56+'Demand Base Matrix'!H$57)*$W$2*$AD$2+'Demand Base Matrix'!H$58*$W$2*$AD$2*$AE$2+'Demand Base Matrix'!H$60+'Demand Base Matrix'!H$61*$AF$2),IF($C6="Explore",('Demand Base Matrix'!H$82*$AC$2*$AD$2*$AE$2*$AF$2+'Demand Base Matrix'!H$83*$W$2*$AC$2*$AD$2*$AE$2*$AF$2+'Demand Base Matrix'!H$84))))) -> 28 | AL6: =IF($C6="Validate",(('Demand Base Matrix'!I$2+'Demand Base Matrix'!I$6)*$AC$2*$AD$2*$AE$2+('Demand Base Matrix'!I$3+'Demand Base Matrix'!I$4)*$W$2*$AD$2+'Demand Base Matrix'!I$5*$W$2*$AD$2*$AE$2+'Demand Base Matrix'!I$7+'Demand Base Matrix'!I$8*$AF$2),IF($C6="Integrate",(('Demand Base Matrix'!I$28+'Demand Base Matrix'!I$32)*$AC$2*$AD$2*$AE$2+('Demand Base Matrix'!I$29+'Demand Base Matrix'!I$30)*$W$2*$AD$2+'Demand Base Matrix'!I$31*$W$2*$AD$2*$AE$2+'Demand Base Matrix'!I$33+'Demand Base Matrix'!I$34*$AF$2),IF($C6="Bond",(('Demand Base Matrix'!I$55+'Demand Base Matrix'!I$59)*$AC$2*$AD$2*$AE$2+('Demand Base Matrix'!I$56+'Demand Base Matrix'!I$57)*$W$2*$AD$2+'Demand Base Matrix'!I$58*$W$2*$AD$2*$AE$2+'Demand Base Matrix'!I$60+'Demand Base Matrix'!I$61*$AF$2),IF($C6="Explore",('Demand Base Matrix'!I$82*$AC$2*$AD$2*$AE$2*$AF$2+'Demand Base Matrix'!I$83*$W$2*$AC$2*$AD$2*$AE$2*$AF$2+'Demand Base Matrix'!I$84))))) -> 8 | AM6: =IF($C6="Validate",(('Demand Base Matrix'!J$2+'Demand Base Matrix'!J$6)*$AC$2*$AD$2*$AE$2+('Demand Base Matrix'!J$3+'Demand Base Matrix'!J$4)*$W$2*$AD$2+'Demand Base Matrix'!J$5*$W$2*$AD$2*$AE$2+'Demand Base Matrix'!J$7+'Demand Base Matrix'!J$8*$AF$2),IF($C6="Integrate",(('Demand Base Matrix'!J$28+'Demand Base Matrix'!J$32)*$AC$2*$AD$2*$AE$2+('Demand Base Matrix'!J$29+'Demand Base Matrix'!J$30)*$W$2*$AD$2+'Demand Base Matrix'!J$31*$W$2*$AD$2*$AE$2+'Demand Base Matrix'!J$33+'Demand Base Matrix'!J$34*$AF$2),IF($C6="Bond",(('Demand Base Matrix'!J$55+'Demand Base Matrix'!J$59)*$AC$2*$AD$2*$AE$2+('Demand Base Matrix'!J$56+'Demand Base Matrix'!J$57)*$W$2*$AD$2+'Demand Base Matrix'!J$58*$W$2*$AD$2*$AE$2+'Demand Base Matrix'!J$60+'Demand Base Matrix'!J$61*$AF$2),IF($C6="Explore",('Demand Base Matrix'!J$82*$AC$2*$AD$2*$AE$2*$AF$2+'Demand Base Matrix'!J$83*$W$2*$AC$2*$AD$2*$AE$2*$AF$2+'Demand Base Matrix'!J$84))))) -> 8
